Workbook

Sheet PLANILLA DE CARGA
A2: PLANILLA DE CARGA DE DATOS | C2: EJEMPLO | BC2: ALGUNOS LOGOTIPOS DE EMPRESAS
B3: 0
A4: DATOS DEMOGRÁFICOS | B4: -2
A5: Número de Observación: | B5: 1.1 | C5: 0 | D5: 1 | E5: 2 | F5: 3 | G5: 4 | H5: 5 | I5: 6 | J5: 7 | K5: 8 | L5: 9 | M5: 10 | N5: 11 | O5: 12 | P5: 13 | Q5: 14 | R5: 15 | S5: 16 | T5: 17 | U5: 18 | V5: 19 | W5: 20 | X5: 21 | Y5: =+X5+1 -> 22 | Z5: =+Y5+1 -> 23 | AA5: =+Z5+1 -> 24 | AB5: =+AA5+1 -> 25 | AC5: =+AB5+1 -> 26 | AD5: =+AC5+1 -> 27 | AE5: =+AD5+1 -> 28 | AF5: =+AE5+1 -> 29 | ... BA5: =+AZ5+1 -> 50
A6: Fecha de Medición (DD/MM/AAAA): | B6: Activa - 19 a 30 años | C6: 45634
A7: Fecha de Nacimiento (DD/MM/AAAA): | B7: Activa - 31 a 50 años | C7: 36475
A8: Edad (años): CARGA AUTOMÁTICA | B8: Activa - Mayor de 50 años | C8: =+(C6-C7)/365.25 -> 25.075975 | D8: 41.856 | E8: 29.506 | F8: 37.61 | G8: 41.161 | H8: 30.053 | I8: 26.185 | J8: 34.048 | K8: 33.473 | L8: 29.58 | M8: 42.494 | N8: 31.715 | O8: 42.784 | P8: 46.678 | Q8: 36.167 | R8: 29.265 | S8: 31.335 | T8: 43.305 | U8: 28.022 | V8: 40.747 | W8: 29.651 | X8: 30.278 | Y8: =+(Y6-Y7)/365.25 -> 0 | Z8: =+(Z6-Z7)/365.25 -> 0 | AA8: =+(AA6-AA7)/365.25 -> 0 | AB8: =+(AB6-AB7)/365.25 -> 0 | AC8: =+(AC6-AC7)/365.25 -> 0 | AD8: =+(AD6-AD7)/365.25 -> 0 | AE8: =+(AE6-AE7)/365.25 -> 0 | AF8: =+(AF6-AF7)/365.25 -> 0 | ... BA8: =+(BA6-BA7)/365.25 -> 0
A9: Nombre y Apellido: | C9: Juana Fantasía
A10: Sexo (Seleccionar de la Lista de Despliegue en la Celda = SLDC): | C10: Femenino
A11: Actividad Física o Referencia (SLDC): | C11: Activa - 19 a 30 años
A12: Raza, Etnia o Grupo Humano (SLDC / ‐2.0 = Asiática / 1.1 = Afroamericana / 0.0 = Blanca o Hispánica): | C12: 0
A13: DATOS ANTROPOMÉTRICOS | B13: Femenino
A14: Talla (cm): | B14: Masculino | C14: 166.3
A15: Peso (kg): | C15: 58
A16: Pliegue Tricipital (mm): | C16: 9
A17: Pliegue Subescapular (mm): | C17: 7
A18: Pliegue Ileocrestal (mm): | C18: 16
A19: Pliegue Abdominal (mm): | C19: 19
A20: Pliegue Muslo Anterior (mm): | C20: 23
A21: Pliegue Pierna Medial (mm): | C21: 12
A22: Perímetro Torácico (cm): | C22: 83.4
A23: Perímetro Cintura (cm): | C23: 65
A24: Perímetro Umbilical (cm): | C24: 66.95
A25: Perímetro Cadera (cm): | C25: 92
A26: Perímetro de Muslo Medio (cm): | C26: 49.6
... A30: Diámetro Biestiloideo de Muñeca (cm): | C30: 5.1

Sheet INF 1º
A2: EVALUACIÓN ANTROPOMÉTRICA
I3: Licenciada Rosana Roldán - www.nuplan.com.ar
J5: 15.75
A6: En DATOS tanto DEMOGRÁFICOS como ANTROPOMÉTRICOS se muestran los valores de la persona medida, y sus resultados en COMPOSICIÓN CORPORAL, en ADIPOSIDAD y en COMPARATIVO DE PERÍMETROS MUSCULARES. | J6: 17.25
J7: 9
A9: DATOS DEMOGRÁFICOS
A11: Nombre y Apellido: | D11: =+'NO TOCAR'!D9 -> 0 | G11: Número de Observación: | I11: =+'NO TOCAR'!D5 -> 1
A12: Sexo: | D12: =+'NO TOCAR'!D10 -> 0 | G12: Fecha de Medición: | I12: =+'NO TOCAR'!D6 -> 0
A13: Actividad Física o Referencia: | D13: =+'NO TOCAR'!D11 -> 0 | G13: Fecha de Nacimiento: | I13: =+'NO TOCAR'!D7 -> 0
A14: Raza, Etnia o Grupo Humano: | D14: =+IF('NO TOCAR'!D12=0,"Blanca o Hispánica",IF('NO TOCAR'!D12=1.1,"Afroamericana","Asiática")) -> Blanca o Hispánica | G14: Edad (años): | I14: =+(I12-I13)/365.25 -> 0
E15: =+'NO TOCAR'!D12 -> 0
A16: DATOS ANTROPOMÉTRICOS
Q17: DATOS REFERENCIALES DE CADA SEXO O GÉNERO
A18: Talla (cm): | E18: =+'NO TOCAR'!D14 -> 0 | F18: Perímetro Torácico (cm): | I18: =+'NO TOCAR'!D22 -> 0
A19: Peso (kg): | E19: =+'NO TOCAR'!D15 -> 0 | F19: Perímetro Cintura (cm): | I19: =+'NO TOCAR'!D23 -> 0
A20: Pliegue Tricipital (mm): | E20: =+'NO TOCAR'!D16 -> 0 | F20: Perímetro Umbilical (cm): | I20: =+'NO TOCAR'!D24 -> 0
A21: Pliegue Subescapular (mm): | E21: =+'NO TOCAR'!D17 -> 0 | F21: Perímetro Cadera (cm): | I21: =+'NO TOCAR'!D25 -> 0
A22: Pliegue Ileocrestal (mm): | E22: =+'NO TOCAR'!D18 -> 0 | F22: Perímetro de Muslo Medio (cm): | I22: =+'NO TOCAR'!D26 -> 0
A23: Pliegue Abdominal (mm): | E23: =+'NO TOCAR'!D19 -> 0 | F23: Perímetro de Pierna (cm): | I23: =+'NO TOCAR'!D27 -> 0 | K23: DATOS REFERENCIALES FINALES | L23: =+Q23 -> #REF! | M23: SEXO | Q23: =+IF($D$13="Activa - 16 a 18 años",Y23,IF($D$13="Activa - 19 a 30 años",AE23,IF($D$13="Activa - 31 a 50 años",AK23,IF($D$13="Activa - Mayor de 50 años",AQ23,IF($D$13="Atletismo de Resistencia",#REF!,IF($D$13="Básquetbol",#REF!,IF($D$13="Fitness Sport",#REF!,IF($D$13="Fútbol",#REF!,IF($D$13="Hockey sobre Césped",#REF!,IF($D$13="Rugby",#REF!,IF($D$13="Tenis",#REF!,#REF!))))))))))) -> #REF! | R23: SEXO | T23: =+IF($D$13="Activa - 16 a 18 años",AB23,IF($D$13="Activa - 19 a 30 años",AH23,IF($D$13="Activa - 31 a 50 años",AN23,IF($D$13="Activa - Mayor de 50 años",AT23,IF($D$13="Atletismo de Resistencia",#REF!,IF($D$13="Básquetbol",#REF!,IF($D$13="Fitness Sport",#REF!,IF($D$13="Fútbol",#REF!,IF($D$13="Hockey sobre Césped",#REF!,IF($D$13="Rugby",#REF!,IF($D$13="Tenis",#REF!,#REF!))))))))))) -> #REF! | U23: SEXO | Y23: Activa - 16 a 18 años | Z23: SEXO | AB23: Activa - 16 a 18 años | AC23: SEXO | AE23: Activa - 19 a 30 años | AF23: SEXO | AH23: Activa - 19 a 30 años | AI23: SEXO | AK23: Activa - 31 a 50 años | AL23: SEXO | AN23: Activa - 31 a 50 años | AO23: SEXO | AQ23: Activa - Mayor de 50 años | AR23: SEXO | AT23: Activa - Mayor de 50 años | AU23: SEXO
A24: Pliegue Muslo Anterior (mm): | E24: =+'NO TOCAR'!D20 -> 0 | F24: Perímetro de Brazo Relajado (cm): | I24: =+'NO TOCAR'!D28 -> 0 | M24: =+IF(D12="Femenino",R24,U24) -> #REF! | R24: =+IF($D$13="Activa - 16 a 18 años",Z24,IF($D$13="Activa - 19 a 30 años",AF24,IF($D$13="Activa - 31 a 50 años",AL24,IF($D$13="Activa - Mayor de 50 años",AR24,IF($D$13="Atletismo de Resistencia",#REF!,IF($D$13="Básquetbol",#REF!,IF($D$13="Fitness Sport",#REF!,IF($D$13="Fútbol",#REF!,IF($D$13="Hockey sobre Césped",#REF!,IF($D$13="Rugby",#REF!,IF($D$13="Tenis",#REF!,#REF!))))))))))) -> #REF! | U24: =+IF($D$13="Activa - 16 a 18 años",AC24,IF($D$13="Activa - 19 a 30 años",AI24,IF($D$13="Activa - 31 a 50 años",AO24,IF($D$13="Activa - Mayor de 50 años",AU24,IF($D$13="Atletismo de Resistencia",#REF!,IF($D$13="Básquetbol",#REF!,IF($D$13="Fitness Sport",#REF!,IF($D$13="Fútbol",#REF!,IF($D$13="Hockey sobre Césped",#REF!,IF($D$13="Rugby",#REF!,IF($D$13="Tenis",#REF!,#REF!))))))))))) -> #REF! | Z24: Femenino | AC24: Masculino | AF24: Femenino | AI24: Masculino | AL24: Femenino | AO24: Masculino | AR24: Femenino | AU24: Masculino
A25: Pliegue Pierna Medial (mm): | E25: =+'NO TOCAR'!D21 -> 0 | F25: Diámetro Bicondíleo de Fémur (cm): | I25: =+'NO TOCAR'!D29 -> 0 | M25: n | R25: n | U25: n | Z25: n | AC25: n | AF25: n | AI25: n | AL25: n | AO25: n | AR25: n | AU25: n
A26: - - - - - - - - - - - - - - - - - - - - - - - - - - - - - - - - - - - - - - - - - - - - - - - - - - - - - - - - | F26: Diámetro Biestiloideo de Muñeca (cm): | I26: =+'NO TOCAR'!D30 -> 0 | M26: =+IF(D12="Femenino",R26,U26) -> #REF! | R26: =+IF($D$13="Activa - 16 a 18 años",Z26,IF($D$13="Activa - 19 a 30 años",AF26,IF($D$13="Activa - 31 a 50 años",AL26,IF($D$13="Activa - Mayor de 50 años",AR26,IF($D$13="Atletismo de Resistencia",#REF!,IF($D$13="Básquetbol",#REF!,IF($D$13="Fitness Sport",#REF!,IF($D$13="Fútbol",#REF!,IF($D$13="Hockey sobre Césped",#REF!,IF($D$13="Rugby",#REF!,IF($D$13="Tenis",#REF!,#REF!))))))))))) -> #REF! | U26: =+IF($D$13="Activa - 16 a 18 años",AC26,IF($D$13="Activa - 19 a 30 años",AI26,IF($D$13="Activa - 31 a 50 años",AO26,IF($D$13="Activa - Mayor de 50 años",AU26,IF($D$13="Atletismo de Resistencia",#REF!,IF($D$13="Básquetbol",#REF!,IF($D$13="Fitness Sport",#REF!,IF($D$13="Fútbol",#REF!,IF($D$13="Hockey sobre Césped",#REF!,IF($D$13="Rugby",#REF!,IF($D$13="Tenis",#REF!,#REF!))))))))))) -> #REF! | Z26: 28 | AC26: 104 | AF26: 55 | AI26: 173 | AL26: 69 | AO26: 163 | AR26: 17 | AU26: 41
A28: VALORES EN COMPOSICIÓN CORPORAL | K28: VARIABLES CORPORALES | L28: MEDIA | M28: D.E. | Q28: MEDIA | R28: D.E. | T28: MEDIA | U28: D.E. | Y28: MEDIA | Z28: D.E. | AB28: MEDIA | AC28: D.E. | AE28: MEDIA | AF28: D.E. | AH28: MEDIA | AI28: D.E. | AK28: MEDIA | AL28: D.E. | AN28: MEDIA | AO28: D.E. | AQ28: MEDIA | AR28: D.E. | AT28: MEDIA | AU28: D.E.
A29: =(0.735*(E20+E25)+1) -> 1 | B29: =(0.61*(E20+E25)+5.1) -> 5.1 | E29: =+(0.29288*(E23+E20+E24+E22)-(0.0005*((E23+E20+E24+E22)^2))+(0.15845*I14)-5.76377) -> -5.76377 | F29: =+(0.29669*(E23+E20+E24+E22)-(0.00043*((E23+E20+E24+E22)^2))+(0.02963*I14)+1.4072) -> 1.4072
A30: Masa Adiposa (%): | E30: =+IF(AND(D12="Femenino",I14<18),B29,IF(AND(D12="Masculino",I14<18),A29,IF(AND(D12="Femenino",I14>=18),F29,E29))) -> -5.76377 | F30: Masa Adiposa (kg): | I30: =+E30*E19/100 -> 0 | K30: PESO (kg): | L30: =+IF($D$12="Femenino",Q30,T30) -> #REF! | M30: =+IF($D$12="Femenino",R30,U30) -> #REF! | Q30: =+IF($D$13="Activa - 16 a 18 años",Y30,IF($D$13="Activa - 19 a 30 años",AE30,IF($D$13="Activa - 31 a 50 años",AK30,IF($D$13="Activa - Mayor de 50 años",AQ30,IF($D$13="Atletismo de Resistencia",#REF!,IF($D$13="Básquetbol",#REF!,IF($D$13="Fitness Sport",#REF!,IF($D$13="Fútbol",#REF!,IF($D$13="Hockey sobre Césped",#REF!,IF($D$13="Rugby",#REF!,IF($D$13="Tenis",#REF!,#REF!))))))))))) -> #REF! | R30: =+IF($D$13="Activa - 16 a 18 años",Z30,IF($D$13="Activa - 19 a 30 años",AF30,IF($D$13="Activa - 31 a 50 años",AL30,IF($D$13="Activa - Mayor de 50 años",AR30,IF($D$13="Atletismo de Resistencia",#REF!,IF($D$13="Básquetbol",#REF!,IF($D$13="Fitness Sport",#REF!,IF($D$13="Fútbol",#REF!,IF($D$13="Hockey sobre Césped",#REF!,IF($D$13="Rugby",#REF!,IF($D$13="Tenis",#REF!,#REF!))))))))))) -> #REF! | T30: =+IF($D$13="Activa - 16 a 18 años",AB30,IF($D$13="Activa - 19 a 30 años",AH30,IF($D$13="Activa - 31 a 50 años",AN30,IF($D$13="Activa - Mayor de 50 años",AT30,IF($D$13="Atletismo de Resistencia",#REF!,IF($D$13="Básquetbol",#REF!,IF($D$13="Fitness Sport",#REF!,IF($D$13="Fútbol",#REF!,IF($D$13="Hockey sobre Césped",#REF!,IF($D$13="Rugby",#REF!,IF($D$13="Tenis",#REF!,#REF!))))))))))) -> #REF! | U30: =+IF($D$13="Activa - 16 a 18 años",AC30,IF($D$13="Activa - 19 a 30 años",AI30,IF($D$13="Activa - 31 a 50 años",AO30,IF($D$13="Activa - Mayor de 50 años",AU30,IF($D$13="Atletismo de Resistencia",#REF!,IF($D$13="Básquetbol",#REF!,IF($D$13="Fitness Sport",#REF!,IF($D$13="Fútbol",#REF!,IF($D$13="Hockey sobre Césped",#REF!,IF($D$13="Rugby",#REF!,IF($D$13="Tenis",#REF!,#REF!))))))))))) -> #REF! | Y30: 59.889286 | Z30: 8.2800223 | AB30: 69.255769 | AC30: 9.6711846 | AE30: 55.922727 | AF30: 7.2048133 | AH30: 75.459249 | AI30: 12.753859 | AK30: 59.762319 | AL30: 9.4506046 | AN30: 80.483129 | AO30: 14.090058 | AQ30: 68.370588 | AR30: 9.7891371 | AT30: 84.168293 | AU30: 14.005672
A31: Referencia (Media ± ½ Desvío): | D31: VA /2 | E31: =+CONCATENATE(FIXED(L33,1)," ± ",FIXED(M33/2,1)) -> #REF! | F31: Referencia (Media ± ½ Desvío): | I31: =+CONCATENATE(FIXED(L32,1)," ± ",FIXED(M32/2,1)) -> #REF! | J31: =+IF(I30<L32-M32*1.5,"Excelente",IF(I30<L32-M32/2,"Muy Buena",IF(I30<=L32+M32/2,"Buena",IF(I30<=L32+M32*1.5,"Regular","No Satisfactoria")))) -> #REF! | K31: TALLA (kg): | L31: =+IF($D$12="Femenino",Q31,T31) -> #REF! | M31: =+IF($D$12="Femenino",R31,U31) -> #REF! | Q31: =+IF($D$13="Activa - 16 a 18 años",Y31,IF($D$13="Activa - 19 a 30 años",AE31,IF($D$13="Activa - 31 a 50 años",AK31,IF($D$13="Activa - Mayor de 50 años",AQ31,IF($D$13="Atletismo de Resistencia",#REF!,IF($D$13="Básquetbol",#REF!,IF($D$13="Fitness Sport",#REF!,IF($D$13="Fútbol",#REF!,IF($D$13="Hockey sobre Césped",#REF!,IF($D$13="Rugby",#REF!,IF($D$13="Tenis",#REF!,#REF!))))))))))) -> #REF! | R31: =+IF($D$13="Activa - 16 a 18 años",Z31,IF($D$13="Activa - 19 a 30 años",AF31,IF($D$13="Activa - 31 a 50 años",AL31,IF($D$13="Activa - Mayor de 50 años",AR31,IF($D$13="Atletismo de Resistencia",#REF!,IF($D$13="Básquetbol",#REF!,IF($D$13="Fitness Sport",#REF!,IF($D$13="Fútbol",#REF!,IF($D$13="Hockey sobre Césped",#REF!,IF($D$13="Rugby",#REF!,IF($D$13="Tenis",#REF!,#REF!))))))))))) -> #REF! | T31: =+IF($D$13="Activa - 16 a 18 años",AB31,IF($D$13="Activa - 19 a 30 años",AH31,IF($D$13="Activa - 31 a 50 años",AN31,IF($D$13="Activa - Mayor de 50 años",AT31,IF($D$13="Atletismo de Resistencia",#REF!,IF($D$13="Básquetbol",#REF!,IF($D$13="Fitness Sport",#REF!,IF($D$13="Fútbol",#REF!,IF($D$13="Hockey sobre Césped",#REF!,IF($D$13="Rugby",#REF!,IF($D$13="Tenis",#REF!,#REF!))))))))))) -> #REF! | U31: =+IF($D$13="Activa - 16 a 18 años",AC31,IF($D$13="Activa - 19 a 30 años",AI31,IF($D$13="Activa - 31 a 50 años",AO31,IF($D$13="Activa - Mayor de 50 años",AU31,IF($D$13="Atletismo de Resistencia",#REF!,IF($D$13="Básquetbol",#REF!,IF($D$13="Fitness Sport",#REF!,IF($D$13="Fútbol",#REF!,IF($D$13="Hockey sobre Césped",#REF!,IF($D$13="Rugby",#REF!,IF($D$13="Tenis",#REF!,#REF!))))))))))) -> #REF! | Y31: 163.49643 | Z31: 6.6638039 | AB31: 174.32115 | AC31: 7.3435749 | AE31: 161.47873 | AF31: 6.133285 | AH31: 175.45665 | AI31: 6.4624609 | AK31: 161.22029 | AL31: 6.0620221 | AN31: 174.20675 | AO31: 7.1526834 | AQ31: 157.42941 | AR31: 4.2245954 | AT31: 174.30732 | AU31: 5.9086119
K32: MASA ADIPOSA (kg): | L32: =+IF($D$12="Femenino",Q32,T32) -> #REF! | M32: =+IF($D$12="Femenino",R32,U32) -> #REF! | Q32: =+IF($D$13="Activa - 16 a 18 años",Y32,IF($D$13="Activa - 19 a 30 años",AE32,IF($D$13="Activa - 31 a 50 años",AK32,IF($D$13="Activa - Mayor de 50 años",AQ32,IF($D$13="Atletismo de Resistencia",#REF!,IF($D$13="Básquetbol",#REF!,IF($D$13="Fitness Sport",#REF!,IF($D$13="Fútbol",#REF!,IF($D$13="Hockey sobre Césped",#REF!,IF($D$13="Rugby",#REF!,IF($D$13="Tenis",#REF!,#REF!))))))))))) -> #REF! | R32: =+IF($D$13="Activa - 16 a 18 años",Z32,IF($D$13="Activa - 19 a 30 años",AF32,IF($D$13="Activa - 31 a 50 años",AL32,IF($D$13="Activa - Mayor de 50 años",AR32,IF($D$13="Atletismo de Resistencia",#REF!,IF($D$13="Básquetbol",#REF!,IF($D$13="Fitness Sport",#REF!,IF($D$13="Fútbol",#REF!,IF($D$13="Hockey sobre Césped",#REF!,IF($D$13="Rugby",#REF!,IF($D$13="Tenis",#REF!,#REF!))))))))))) -> #REF! | T32: =+IF($D$13="Activa - 16 a 18 años",AB32,IF($D$13="Activa - 19 a 30 años",AH32,IF($D$13="Activa - 31 a 50 años",AN32,IF($D$13="Activa - Mayor de 50 años",AT32,IF($D$13="Atletismo de Resistencia",#REF!,IF($D$13="Básquetbol",#REF!,IF($D$13="Fitness Sport",#REF!,IF($D$13="Fútbol",#REF!,IF($D$13="Hockey sobre Césped",#REF!,IF($D$13="Rugby",#REF!,IF($D$13="Tenis",#REF!,#REF!))))))))))) -> #REF! | U32: =+IF($D$13="Activa - 16 a 18 años",AC32,IF($D$13="Activa - 19 a 30 años",AI32,IF($D$13="Activa - 31 a 50 años",AO32,IF($D$13="Activa - Mayor de 50 años",AU32,IF($D$13="Atletismo de Resistencia",#REF!,IF($D$13="Básquetbol",#REF!,IF($D$13="Fitness Sport",#REF!,IF($D$13="Fútbol",#REF!,IF($D$13="Hockey sobre Césped",#REF!,IF($D$13="Rugby",#REF!,IF($D$13="Tenis",#REF!,#REF!))))))))))) -> #REF! | Y32: 15.12565 | Z32: 4.7014942 | AB32: 10.696169 | AC32: 5.1149452 | AE32: 12.381169 | AF32: 4.3077838 | AH32: 10.920301 | AI32: 7.1803911 | AK32: 14.242999 | AL32: 5.8936537 | AN32: 16.693186 | AO32: 8.1510109 | AQ32: 21.006161 | AR32: 6.2233103 | AT32: 21.534002 | AU32: 8.7308852
A33: Masa Muscular (%): | E33: =+I33*100/E19 -> #DIV/0! | F33: Masa Muscular (kg): | I33: =+(E18/100)*(0.00744*(I24-3.1416*(E20/10))^2+0.00088*(I22-3.1416*(E24/10))^2+0.00441*(I23-3.1416*(E25/10))^2)+(2.4*(IF(D12="Masculino",1,0)))-(0.048*I14)+E15+7.8 -> 7.8 | K33: MASA ADIPOSA (%): | L33: =+IF($D$12="Femenino",Q33,T33) -> #REF! | M33: =+IF($D$12="Femenino",R33,U33) -> #REF! | Q33: =+IF($D$13="Activa - 16 a 18 años",Y33,IF($D$13="Activa - 19 a 30 años",AE33,IF($D$13="Activa - 31 a 50 años",AK33,IF($D$13="Activa - Mayor de 50 años",AQ33,IF($D$13="Atletismo de Resistencia",#REF!,IF($D$13="Básquetbol",#REF!,IF($D$13="Fitness Sport",#REF!,IF($D$13="Fútbol",#REF!,IF($D$13="Hockey sobre Césped",#REF!,IF($D$13="Rugby",#REF!,IF($D$13="Tenis",#REF!,#REF!))))))))))) -> #REF! | R33: =+IF($D$13="Activa - 16 a 18 años",Z33,IF($D$13="Activa - 19 a 30 años",AF33,IF($D$13="Activa - 31 a 50 años",AL33,IF($D$13="Activa - Mayor de 50 años",AR33,IF($D$13="Atletismo de Resistencia",#REF!,IF($D$13="Básquetbol",#REF!,IF($D$13="Fitness Sport",#REF!,IF($D$13="Fútbol",#REF!,IF($D$13="Hockey sobre Césped",#REF!,IF($D$13="Rugby",#REF!,IF($D$13="Tenis",#REF!,#REF!))))))))))) -> #REF! | T33: =+IF($D$13="Activa - 16 a 18 años",AB33,IF($D$13="Activa - 19 a 30 años",AH33,IF($D$13="Activa - 31 a 50 años",AN33,IF($D$13="Activa - Mayor de 50 años",AT33,IF($D$13="Atletismo de Resistencia",#REF!,IF($D$13="Básquetbol",#REF!,IF($D$13="Fitness Sport",#REF!,IF($D$13="Fútbol",#REF!,IF($D$13="Hockey sobre Césped",#REF!,IF($D$13="Rugby",#REF!,IF($D$13="Tenis",#REF!,#REF!))))))))))) -> #REF! | U33: =+IF($D$13="Activa - 16 a 18 años",AC33,IF($D$13="Activa - 19 a 30 años",AI33,IF($D$13="Activa - 31 a 50 años",AO33,IF($D$13="Activa - Mayor de 50 años",AU33,IF($D$13="Atletismo de Resistencia",#REF!,IF($D$13="Básquetbol",#REF!,IF($D$13="Fitness Sport",#REF!,IF($D$13="Fútbol",#REF!,IF($D$13="Hockey sobre Césped",#REF!,IF($D$13="Rugby",#REF!,IF($D$13="Tenis",#REF!,#REF!))))))))))) -> #REF! | Y33: 25.066607 | Z33: 5.8554364 | AB33: 15.201755 | AC33: 5.9492562 | AE33: 21.770553 | AF33: 5.1861666 | AH33: 13.689817 | AI33: 6.8496419 | AK33: 23.084948 | AL33: 6.4873064 | AN33: 19.987753 | AO33: 6.516567 | AQ33: 30.137324 | AR33: 5.5134903 | AT33: 24.855993 | AU33: 6.1267433
A34: Referencia (Media ± ½ Desvío): | E34: =+CONCATENATE(FIXED(L35,1)," ± ",FIXED(M35/2,1)) -> #REF! | F34: Referencia (Media ± ½ Desvío): | I34: =+CONCATENATE(FIXED(L34,1)," ± ",FIXED(M34/2,1)) -> #REF! | J34: =+IF(I33>L34+M34*1.5,"Excelente",IF(I33>L34+M34/2,"Muy Bueno",IF(I33>=L34-M34/2,"Bueno",IF(I33>=L34-M34*1.5,"Regular","No Satisfactorio")))) -> #REF! | K34: MASA MUSCULAR (kg): | L34: =+IF($D$12="Femenino",Q34,T34) -> #REF! | M34: =+IF($D$12="Femenino",R34,U34) -> #REF! | Q34: =+IF($D$13="Activa - 16 a 18 años",Y34,IF($D$13="Activa - 19 a 30 años",AE34,IF($D$13="Activa - 31 a 50 años",AK34,IF($D$13="Activa - Mayor de 50 años",AQ34,IF($D$13="Atletismo de Resistencia",#REF!,IF($D$13="Básquetbol",#REF!,IF($D$13="Fitness Sport",#REF!,IF($D$13="Fútbol",#REF!,IF($D$13="Hockey sobre Césped",#REF!,IF($D$13="Rugby",#REF!,IF($D$13="Tenis",#REF!,#REF!))))))))))) -> #REF! | R34: =+IF($D$13="Activa - 16 a 18 años",Z34,IF($D$13="Activa - 19 a 30 años",AF34,IF($D$13="Activa - 31 a 50 años",AL34,IF($D$13="Activa - Mayor de 50 años",AR34,IF($D$13="Atletismo de Resistencia",#REF!,IF($D$13="Básquetbol",#REF!,IF($D$13="Fitness Sport",#REF!,IF($D$13="Fútbol",#REF!,IF($D$13="Hockey sobre Césped",#REF!,IF($D$13="Rugby",#REF!,IF($D$13="Tenis",#REF!,#REF!))))))))))) -> #REF! | T34: =+IF($D$13="Activa - 16 a 18 años",AB34,IF($D$13="Activa - 19 a 30 años",AH34,IF($D$13="Activa - 31 a 50 años",AN34,IF($D$13="Activa - Mayor de 50 años",AT34,IF($D$13="Atletismo de Resistencia",#REF!,IF($D$13="Básquetbol",#REF!,IF($D$13="Fitness Sport",#REF!,IF($D$13="Fútbol",#REF!,IF($D$13="Hockey sobre Césped",#REF!,IF($D$13="Rugby",#REF!,IF($D$13="Tenis",#REF!,#REF!))))))))))) -> #REF! | U34: =+IF($D$13="Activa - 16 a 18 años",AC34,IF($D$13="Activa - 19 a 30 años",AI34,IF($D$13="Activa - 31 a 50 años",AO34,IF($D$13="Activa - Mayor de 50 años",AU34,IF($D$13="Atletismo de Resistencia",#REF!,IF($D$13="Básquetbol",#REF!,IF($D$13="Fitness Sport",#REF!,IF($D$13="Fútbol",#REF!,IF($D$13="Hockey sobre Césped",#REF!,IF($D$13="Rugby",#REF!,IF($D$13="Tenis",#REF!,#REF!))))))))))) -> #REF! | Y34: 21.39283 | Z34: 2.4830093 | AB34: 29.863816 | AC34: 3.3831829 | AE34: 20.28566 | AF34: 1.8217342 | AH34: 31.444974 | AI34: 3.8720819 | AK34: 20.768183 | AL34: 2.0123254 | AN34: 31.543881 | AO34: 4.1832887 | AQ34: 20.253511 | AR34: 2.2490133 | AT34: 29.754901 | AU34: 3.2538854
K35: MASA MUSCULAR (%): | L35: =+IF($D$12="Femenino",Q35,T35) -> #REF! | M35: =+IF($D$12="Femenino",R35,U35) -> #REF! | Q35: =+IF($D$13="Activa - 16 a 18 años",Y35,IF($D$13="Activa - 19 a 30 años",AE35,IF($D$13="Activa - 31 a 50 años",AK35,IF($D$13="Activa - Mayor de 50 años",AQ35,IF($D$13="Atletismo de Resistencia",#REF!,IF($D$13="Básquetbol",#REF!,IF($D$13="Fitness Sport",#REF!,IF($D$13="Fútbol",#REF!,IF($D$13="Hockey sobre Césped",#REF!,IF($D$13="Rugby",#REF!,IF($D$13="Tenis",#REF!,#REF!))))))))))) -> #REF! | R35: =+IF($D$13="Activa - 16 a 18 años",Z35,IF($D$13="Activa - 19 a 30 años",AF35,IF($D$13="Activa - 31 a 50 años",AL35,IF($D$13="Activa - Mayor de 50 años",AR35,IF($D$13="Atletismo de Resistencia",#REF!,IF($D$13="Básquetbol",#REF!,IF($D$13="Fitness Sport",#REF!,IF($D$13="Fútbol",#REF!,IF($D$13="Hockey sobre Césped",#REF!,IF($D$13="Rugby",#REF!,IF($D$13="Tenis",#REF!,#REF!))))))))))) -> #REF! | T35: =+IF($D$13="Activa - 16 a 18 años",AB35,IF($D$13="Activa - 19 a 30 años",AH35,IF($D$13="Activa - 31 a 50 años",AN35,IF($D$13="Activa - Mayor de 50 años",AT35,IF($D$13="Atletismo de Resistencia",#REF!,IF($D$13="Básquetbol",#REF!,IF($D$13="Fitness Sport",#REF!,IF($D$13="Fútbol",#REF!,IF($D$13="Hockey sobre Césped",#REF!,IF($D$13="Rugby",#REF!,IF($D$13="Tenis",#REF!,#REF!))))))))))) -> #REF! | U35: =+IF($D$13="Activa - 16 a 18 años",AC35,IF($D$13="Activa - 19 a 30 años",AI35,IF($D$13="Activa - 31 a 50 años",AO35,IF($D$13="Activa - Mayor de 50 años",AU35,IF($D$13="Atletismo de Resistencia",#REF!,IF($D$13="Básquetbol",#REF!,IF($D$13="Fitness Sport",#REF!,IF($D$13="Fútbol",#REF!,IF($D$13="Hockey sobre Césped",#REF!,IF($D$13="Rugby",#REF!,IF($D$13="Tenis",#REF!,#REF!))))))))))) -> #REF! | Y35: 35.957258 | Z35: 3.3085227 | AB35: 43.389186 | AC35: 3.4296716 | AE35: 36.529439 | AF35: 3.021446 | AH35: 42.115163 | AI35: 4.0338265 | AK35: 35.242926 | AL35: 4.0108793 | AN35: 39.702496 | AO35: 4.6387654 | AQ35: 29.962934 | AR35: 3.8117558 | AT35: 35.895502 | AU35: 4.4764022
A36: Masa Ósea (%): | E36: =+I36*100/E19 -> #DIV/0! | F36: Masa Ósea (kg): | I36: =3.02*((E18/100)^2*(I26/100)*(I25/100)*400)^0.712 -> 0 | K36: MASA ÓSEA (kg): | L36: =+IF($D$12="Femenino",Q36,T36) -> #REF! | M36: =+IF($D$12="Femenino",R36,U36) -> #REF! | Q36: =+IF($D$13="Activa - 16 a 18 años",Y36,IF($D$13="Activa - 19 a 30 años",AE36,IF($D$13="Activa - 31 a 50 años",AK36,IF($D$13="Activa - Mayor de 50 años",AQ36,IF($D$13="Atletismo de Resistencia",#REF!,IF($D$13="Básquetbol",#REF!,IF($D$13="Fitness Sport",#REF!,IF($D$13="Fútbol",#REF!,IF($D$13="Hockey sobre Césped",#REF!,IF($D$13="Rugby",#REF!,IF($D$13="Tenis",#REF!,#REF!))))))))))) -> #REF! | R36: =+IF($D$13="Activa - 16 a 18 años",Z36,IF($D$13="Activa - 19 a 30 años",AF36,IF($D$13="Activa - 31 a 50 años",AL36,IF($D$13="Activa - Mayor de 50 años",AR36,IF($D$13="Atletismo de Resistencia",#REF!,IF($D$13="Básquetbol",#REF!,IF($D$13="Fitness Sport",#REF!,IF($D$13="Fútbol",#REF!,IF($D$13="Hockey sobre Césped",#REF!,IF($D$13="Rugby",#REF!,IF($D$13="Tenis",#REF!,#REF!))))))))))) -> #REF! | T36: =+IF($D$13="Activa - 16 a 18 años",AB36,IF($D$13="Activa - 19 a 30 años",AH36,IF($D$13="Activa - 31 a 50 años",AN36,IF($D$13="Activa - Mayor de 50 años",AT36,IF($D$13="Atletismo de Resistencia",#REF!,IF($D$13="Básquetbol",#REF!,IF($D$13="Fitness Sport",#REF!,IF($D$13="Fútbol",#REF!,IF($D$13="Hockey sobre Césped",#REF!,IF($D$13="Rugby",#REF!,IF($D$13="Tenis",#REF!,#REF!))))))))))) -> #REF! | U36: =+IF($D$13="Activa - 16 a 18 años",AC36,IF($D$13="Activa - 19 a 30 años",AI36,IF($D$13="Activa - 31 a 50 años",AO36,IF($D$13="Activa - Mayor de 50 años",AU36,IF($D$13="Atletismo de Resistencia",#REF!,IF($D$13="Básquetbol",#REF!,IF($D$13="Fitness Sport",#REF!,IF($D$13="Fútbol",#REF!,IF($D$13="Hockey sobre Césped",#REF!,IF($D$13="Rugby",#REF!,IF($D$13="Tenis",#REF!,#REF!))))))))))) -> #REF! | Y36: 9.4314851 | Z36: 1.1422662 | AB36: 11.716237 | AC36: 1.4142277 | AE36: 8.9743868 | AF36: 1.1179564 | AH36: 11.908046 | AI36: 1.3427458 | AK36: 8.9256001 | AL36: 0.81738484 | AN36: 11.880456 | AO36: 1.5178993 | AQ36: 8.9090948 | AR36: 0.69621109 | AT36: 11.939689 | AU36: 1.3919204
A37: Referencia (Media ± ½ Desvío): | E37: =+CONCATENATE(FIXED(L37,1)," ± ",FIXED(M37/2,1)) -> #REF! | F37: Referencia (Media ± ½ Desvío): | I37: =+CONCATENATE(FIXED(L36,1)," ± ",FIXED(M36/2,1)) -> #REF! | J37: =+IF(I36>L36+M36*1.5,"Excelente",IF(I36>L36+M36/2,"Muy Bueno",IF(I36>=L36-M36/2,"Bueno",IF(I36>=L36-M36*1.5,"Regular","No Satisfactorio")))) -> #REF! | K37: MASA ÓSEA (%): | L37: =+IF($D$12="Femenino",Q37,T37) -> #REF! | M37: =+IF($D$12="Femenino",R37,U37) -> #REF! | Q37: =+IF($D$13="Activa - 16 a 18 años",Y37,IF($D$13="Activa - 19 a 30 años",AE37,IF($D$13="Activa - 31 a 50 años",AK37,IF($D$13="Activa - Mayor de 50 años",AQ37,IF($D$13="Atletismo de Resistencia",#REF!,IF($D$13="Básquetbol",#REF!,IF($D$13="Fitness Sport",#REF!,IF($D$13="Fútbol",#REF!,IF($D$13="Hockey sobre Césped",#REF!,IF($D$13="Rugby",#REF!,IF($D$13="Tenis",#REF!,#REF!))))))))))) -> #REF! | R37: =+IF($D$13="Activa - 16 a 18 años",Z37,IF($D$13="Activa - 19 a 30 años",AF37,IF($D$13="Activa - 31 a 50 años",AL37,IF($D$13="Activa - Mayor de 50 años",AR37,IF($D$13="Atletismo de Resistencia",#REF!,IF($D$13="Básquetbol",#REF!,IF($D$13="Fitness Sport",#REF!,IF($D$13="Fútbol",#REF!,IF($D$13="Hockey sobre Césped",#REF!,IF($D$13="Rugby",#REF!,IF($D$13="Tenis",#REF!,#REF!))))))))))) -> #REF! | T37: =+IF($D$13="Activa - 16 a 18 años",AB37,IF($D$13="Activa - 19 a 30 años",AH37,IF($D$13="Activa - 31 a 50 años",AN37,IF($D$13="Activa - Mayor de 50 años",AT37,IF($D$13="Atletismo de Resistencia",#REF!,IF($D$13="Básquetbol",#REF!,IF($D$13="Fitness Sport",#REF!,IF($D$13="Fútbol",#REF!,IF($D$13="Hockey sobre Césped",#REF!,IF($D$13="Rugby",#REF!,IF($D$13="Tenis",#REF!,#REF!))))))))))) -> #REF! | U37: =+IF($D$13="Activa - 16 a 18 años",AC37,IF($D$13="Activa - 19 a 30 años",AI37,IF($D$13="Activa - 31 a 50 años",AO37,IF($D$13="Activa - Mayor de 50 años",AU37,IF($D$13="Atletismo de Resistencia",#REF!,IF($D$13="Básquetbol",#REF!,IF($D$13="Fitness Sport",#REF!,IF($D$13="Fútbol",#REF!,IF($D$13="Hockey sobre Césped",#REF!,IF($D$13="Rugby",#REF!,IF($D$13="Tenis",#REF!,#REF!))))))))))) -> #REF! | Y37: 15.842581 | Z37: 1.4087503 | AB37: 17.045268 | AC37: 1.7180326 | AE37: 16.144382 | AF37: 1.7318375 | AH37: 15.992367 | AI37: 1.8093693 | AK37: 15.174354 | AL37: 1.910052 | AN37: 14.94432 | AO37: 1.6940524 | AQ37: 13.195272 | AR37: 1.4556596 | AT37: 14.367362 | AU37: 1.6540378
K38: ADIPOSIDAD REGIÓN SUPERIOR (%) | L38: =+IF($D$12="Femenino",Q38,T38) -> #REF! | M38: =+IF($D$12="Femenino",R38,U38) -> #REF! | Q38: =+IF($D$13="Activa - 16 a 18 años",Y38,IF($D$13="Activa - 19 a 30 años",AE38,IF($D$13="Activa - 31 a 50 años",AK38,IF($D$13="Activa - Mayor de 50 años",AQ38,IF($D$13="Atletismo de Resistencia",#REF!,IF($D$13="Básquetbol",#REF!,IF($D$13="Fitness Sport",#REF!,IF($D$13="Fútbol",#REF!,IF($D$13="Hockey sobre Césped",#REF!,IF($D$13="Rugby",#REF!,IF($D$13="Tenis",#REF!,#REF!))))))))))) -> #REF! | R38: =+IF($D$13="Activa - 16 a 18 años",Z38,IF($D$13="Activa - 19 a 30 años",AF38,IF($D$13="Activa - 31 a 50 años",AL38,IF($D$13="Activa - Mayor de 50 años",AR38,IF($D$13="Atletismo de Resistencia",#REF!,IF($D$13="Básquetbol",#REF!,IF($D$13="Fitness Sport",#REF!,IF($D$13="Fútbol",#REF!,IF($D$13="Hockey sobre Césped",#REF!,IF($D$13="Rugby",#REF!,IF($D$13="Tenis",#REF!,#REF!))))))))))) -> #REF! | T38: =+IF($D$13="Activa - 16 a 18 años",AB38,IF($D$13="Activa - 19 a 30 años",AH38,IF($D$13="Activa - 31 a 50 años",AN38,IF($D$13="Activa - Mayor de 50 años",AT38,IF($D$13="Atletismo de Resistencia",#REF!,IF($D$13="Básquetbol",#REF!,IF($D$13="Fitness Sport",#REF!,IF($D$13="Fútbol",#REF!,IF($D$13="Hockey sobre Césped",#REF!,IF($D$13="Rugby",#REF!,IF($D$13="Tenis",#REF!,#REF!))))))))))) -> #REF! | U38: =+IF($D$13="Activa - 16 a 18 años",AC38,IF($D$13="Activa - 19 a 30 años",AI38,IF($D$13="Activa - 31 a 50 años",AO38,IF($D$13="Activa - Mayor de 50 años",AU38,IF($D$13="Atletismo de Resistencia",#REF!,IF($D$13="Básquetbol",#REF!,IF($D$13="Fitness Sport",#REF!,IF($D$13="Fútbol",#REF!,IF($D$13="Hockey sobre Césped",#REF!,IF($D$13="Rugby",#REF!,IF($D$13="Tenis",#REF!,#REF!))))))))))) -> #REF! | Y38: 28.362704 | Z38: 2.411465 | AB38: 30.627925 | AC38: 3.4586279 | AE38: 28.847009 | AF38: 2.6759614 | AH38: 29.892234 | AI38: 2.9832143 | AK38: 30.801832 | AL38: 3.0497153 | AN38: 29.932635 | AO38: 2.8936992 | AQ38: 32.478959 | AR38: 3.5075767 | AT38: 30.964377 | AU38: 3.0400861
K39: ADIPOSIDAD REGIÓN MEDIA (%) | L39: =+IF($D$12="Femenino",Q39,T39) -> #REF! | M39: =+IF($D$12="Femenino",R39,U39) -> #REF! | Q39: =+IF($D$13="Activa - 16 a 18 años",Y39,IF($D$13="Activa - 19 a 30 años",AE39,IF($D$13="Activa - 31 a 50 años",AK39,IF($D$13="Activa - Mayor de 50 años",AQ39,IF($D$13="Atletismo de Resistencia",#REF!,IF($D$13="Básquetbol",#REF!,IF($D$13="Fitness Sport",#REF!,IF($D$13="Fútbol",#REF!,IF($D$13="Hockey sobre Césped",#REF!,IF($D$13="Rugby",#REF!,IF($D$13="Tenis",#REF!,#REF!))))))))))) -> #REF! | R39: =+IF($D$13="Activa - 16 a 18 años",Z39,IF($D$13="Activa - 19 a 30 años",AF39,IF($D$13="Activa - 31 a 50 años",AL39,IF($D$13="Activa - Mayor de 50 años",AR39,IF($D$13="Atletismo de Resistencia",#REF!,IF($D$13="Básquetbol",#REF!,IF($D$13="Fitness Sport",#REF!,IF($D$13="Fútbol",#REF!,IF($D$13="Hockey sobre Césped",#REF!,IF($D$13="Rugby",#REF!,IF($D$13="Tenis",#REF!,#REF!))))))))))) -> #REF! | T39: =+IF($D$13="Activa - 16 a 18 años",AB39,IF($D$13="Activa - 19 a 30 años",AH39,IF($D$13="Activa - 31 a 50 años",AN39,IF($D$13="Activa - Mayor de 50 años",AT39,IF($D$13="Atletismo de Resistencia",#REF!,IF($D$13="Básquetbol",#REF!,IF($D$13="Fitness Sport",#REF!,IF($D$13="Fútbol",#REF!,IF($D$13="Hockey sobre Césped",#REF!,IF($D$13="Rugby",#REF!,IF($D$13="Tenis",#REF!,#REF!))))))))))) -> #REF! | U39: =+IF($D$13="Activa - 16 a 18 años",AC39,IF($D$13="Activa - 19 a 30 años",AI39,IF($D$13="Activa - 31 a 50 años",AO39,IF($D$13="Activa - Mayor de 50 años",AU39,IF($D$13="Atletismo de Resistencia",#REF!,IF($D$13="Básquetbol",#REF!,IF($D$13="Fitness Sport",#REF!,IF($D$13="Fútbol",#REF!,IF($D$13="Hockey sobre Césped",#REF!,IF($D$13="Rugby",#REF!,IF($D$13="Tenis",#REF!,#REF!))))))))))) -> #REF! | Y39: 35.263817 | Z39: 4.3515779 | AB39: 36.3752 | AC39: 5.3298079 | AE39: 33.916675 | AF39: 4.1936008 | AH39: 38.788964 | AI39: 4.6757614 | AK39: 32.344127 | AL39: 4.9942506 | AN39: 40.865533 | AO39: 3.2901627 | AQ39: 33.45772 | AR39: 3.3688064 | AT39: 41.013559 | AU39: 2.5376019
D40: Adiposo | F40: =+E30 -> -5.76377 | K40: ADIPOSIDAD REGIÓN INFERIOR (%) | L40: =+IF($D$12="Femenino",Q40,T40) -> #REF! | M40: =+IF($D$12="Femenino",R40,U40) -> #REF! | Q40: =+IF($D$13="Activa - 16 a 18 años",Y40,IF($D$13="Activa - 19 a 30 años",AE40,IF($D$13="Activa - 31 a 50 años",AK40,IF($D$13="Activa - Mayor de 50 años",AQ40,IF($D$13="Atletismo de Resistencia",#REF!,IF($D$13="Básquetbol",#REF!,IF($D$13="Fitness Sport",#REF!,IF($D$13="Fútbol",#REF!,IF($D$13="Hockey sobre Césped",#REF!,IF($D$13="Rugby",#REF!,IF($D$13="Tenis",#REF!,#REF!))))))))))) -> #REF! | R40: =+IF($D$13="Activa - 16 a 18 años",Z40,IF($D$13="Activa - 19 a 30 años",AF40,IF($D$13="Activa - 31 a 50 años",AL40,IF($D$13="Activa - Mayor de 50 años",AR40,IF($D$13="Atletismo de Resistencia",#REF!,IF($D$13="Básquetbol",#REF!,IF($D$13="Fitness Sport",#REF!,IF($D$13="Fútbol",#REF!,IF($D$13="Hockey sobre Césped",#REF!,IF($D$13="Rugby",#REF!,IF($D$13="Tenis",#REF!,#REF!))))))))))) -> #REF! | T40: =+IF($D$13="Activa - 16 a 18 años",AB40,IF($D$13="Activa - 19 a 30 años",AH40,IF($D$13="Activa - 31 a 50 años",AN40,IF($D$13="Activa - Mayor de 50 años",AT40,IF($D$13="Atletismo de Resistencia",#REF!,IF($D$13="Básquetbol",#REF!,IF($D$13="Fitness Sport",#REF!,IF($D$13="Fútbol",#REF!,IF($D$13="Hockey sobre Césped",#REF!,IF($D$13="Rugby",#REF!,IF($D$13="Tenis",#REF!,#REF!))))))))))) -> #REF! | U40: =+IF($D$13="Activa - 16 a 18 años",AC40,IF($D$13="Activa - 19 a 30 años",AI40,IF($D$13="Activa - 31 a 50 años",AO40,IF($D$13="Activa - Mayor de 50 años",AU40,IF($D$13="Atletismo de Resistencia",#REF!,IF($D$13="Básquetbol",#REF!,IF($D$13="Fitness Sport",#REF!,IF($D$13="Fútbol",#REF!,IF($D$13="Hockey sobre Césped",#REF!,IF($D$13="Rugby",#REF!,IF($D$13="Tenis",#REF!,#REF!))))))))))) -> #REF! | Y40: 36.37348 | Z40: 3.8901165 | AB40: 32.996875 | AC40: 4.3957247 | AE40: 37.236316 | AF40: 3.7237692 | AH40: 31.318802 | AI40: 3.9937165 | AK40: 36.85404 | AL40: 4.9576292 | AN40: 29.201832 | AO40: 3.0616182 | AQ40: 34.063321 | AR40: 3.8293036 | AT40: 28.022063 | AU40: 2.7960704
D41: Muscular | F41: =+E33 -> #DIV/0! | K41: PERÍMETRO TORÁCICO (cm): | L41: =+IF($D$12="Femenino",Q41,T41) -> #REF! | M41: =+IF($D$12="Femenino",R41,U41) -> #REF! | Q41: =+IF($D$13="Activa - 16 a 18 años",Y41,IF($D$13="Activa - 19 a 30 años",AE41,IF($D$13="Activa - 31 a 50 años",AK41,IF($D$13="Activa - Mayor de 50 años",AQ41,IF($D$13="Atletismo de Resistencia",#REF!,IF($D$13="Básquetbol",#REF!,IF($D$13="Fitness Sport",#REF!,IF($D$13="Fútbol",#REF!,IF($D$13="Hockey sobre Césped",#REF!,IF($D$13="Rugby",#REF!,IF($D$13="Tenis",#REF!,#REF!))))))))))) -> #REF! | R41: =+IF($D$13="Activa - 16 a 18 años",Z41,IF($D$13="Activa - 19 a 30 años",AF41,IF($D$13="Activa - 31 a 50 años",AL41,IF($D$13="Activa - Mayor de 50 años",AR41,IF($D$13="Atletismo de Resistencia",#REF!,IF($D$13="Básquetbol",#REF!,IF($D$13="Fitness Sport",#REF!,IF($D$13="Fútbol",#REF!,IF($D$13="Hockey sobre Césped",#REF!,IF($D$13="Rugby",#REF!,IF($D$13="Tenis",#REF!,#REF!))))))))))) -> #REF! | T41: =+IF($D$13="Activa - 16 a 18 años",AB41,IF($D$13="Activa - 19 a 30 años",AH41,IF($D$13="Activa - 31 a 50 años",AN41,IF($D$13="Activa - Mayor de 50 años",AT41,IF($D$13="Atletismo de Resistencia",#REF!,IF($D$13="Básquetbol",#REF!,IF($D$13="Fitness Sport",#REF!,IF($D$13="Fútbol",#REF!,IF($D$13="Hockey sobre Césped",#REF!,IF($D$13="Rugby",#REF!,IF($D$13="Tenis",#REF!,#REF!))))))))))) -> #REF! | U41: =+IF($D$13="Activa - 16 a 18 años",AC41,IF($D$13="Activa - 19 a 30 años",AI41,IF($D$13="Activa - 31 a 50 años",AO41,IF($D$13="Activa - Mayor de 50 años",AU41,IF($D$13="Atletismo de Resistencia",#REF!,IF($D$13="Básquetbol",#REF!,IF($D$13="Fitness Sport",#REF!,IF($D$13="Fútbol",#REF!,IF($D$13="Hockey sobre Césped",#REF!,IF($D$13="Rugby",#REF!,IF($D$13="Tenis",#REF!,#REF!))))))))))) -> #REF! | Y41: 86.678571 | Z41: 5.8722421 | AB41: 91.131731 | AC41: 5.8911199 | AE41: 84.423636 | AF41: 4.8589346 | AH41: 97.112139 | AI41: 9.8655097 | AK41: 87.884058 | AL41: 6.6396231 | AN41: 101.40982 | AO41: 9.0595643 | AQ41: 96.764706 | AR41: 7.0069556 | AT41: 105.02439 | AU41: 8.6222033
D42: Óseo | F42: =+E36 -> #DIV/0! | K42: PERÍMETRO CINTURA (cm): | L42: =+IF($D$12="Femenino",Q42,T42) -> #REF! | M42: =+IF($D$12="Femenino",R42,U42) -> #REF! | Q42: =+IF($D$13="Activa - 16 a 18 años",Y42,IF($D$13="Activa - 19 a 30 años",AE42,IF($D$13="Activa - 31 a 50 años",AK42,IF($D$13="Activa - Mayor de 50 años",AQ42,IF($D$13="Atletismo de Resistencia",#REF!,IF($D$13="Básquetbol",#REF!,IF($D$13="Fitness Sport",#REF!,IF($D$13="Fútbol",#REF!,IF($D$13="Hockey sobre Césped",#REF!,IF($D$13="Rugby",#REF!,IF($D$13="Tenis",#REF!,#REF!))))))))))) -> #REF! | R42: =+IF($D$13="Activa - 16 a 18 años",Z42,IF($D$13="Activa - 19 a 30 años",AF42,IF($D$13="Activa - 31 a 50 años",AL42,IF($D$13="Activa - Mayor de 50 años",AR42,IF($D$13="Atletismo de Resistencia",#REF!,IF($D$13="Básquetbol",#REF!,IF($D$13="Fitness Sport",#REF!,IF($D$13="Fútbol",#REF!,IF($D$13="Hockey sobre Césped",#REF!,IF($D$13="Rugby",#REF!,IF($D$13="Tenis",#REF!,#REF!))))))))))) -> #REF! | T42: =+IF($D$13="Activa - 16 a 18 años",AB42,IF($D$13="Activa - 19 a 30 años",AH42,IF($D$13="Activa - 31 a 50 años",AN42,IF($D$13="Activa - Mayor de 50 años",AT42,IF($D$13="Atletismo de Resistencia",#REF!,IF($D$13="Básquetbol",#REF!,IF($D$13="Fitness Sport",#REF!,IF($D$13="Fútbol",#REF!,IF($D$13="Hockey sobre Césped",#REF!,IF($D$13="Rugby",#REF!,IF($D$13="Tenis",#REF!,#REF!))))))))))) -> #REF! | U42: =+IF($D$13="Activa - 16 a 18 años",AC42,IF($D$13="Activa - 19 a 30 años",AI42,IF($D$13="Activa - 31 a 50 años",AO42,IF($D$13="Activa - Mayor de 50 años",AU42,IF($D$13="Atletismo de Resistencia",#REF!,IF($D$13="Básquetbol",#REF!,IF($D$13="Fitness Sport",#REF!,IF($D$13="Fútbol",#REF!,IF($D$13="Hockey sobre Césped",#REF!,IF($D$13="Rugby",#REF!,IF($D$13="Tenis",#REF!,#REF!))))))))))) -> #REF! | Y42: 71.577589 | Z42: 7.035649 | AB42: 73.071149 | AC42: 7.9644355 | AE42: 69.309 | AF42: 7.1195988 | AH42: 79.076139 | AI42: 9.8526167 | AK42: 72.995043 | AL42: 8.7474753 | AN42: 85.867417 | AO42: 10.718134 | AQ42: 83.16 | AR42: 10.119416 | AT42: 93.381415 | AU42: 12.12986
D43: Residual | F43: =100-F40-F41-F42 -> #DIV/0! | K43: PERÍMETRO CADERA (cm): | L43: =+IF($D$12="Femenino",Q43,T43) -> #REF! | M43: =+IF($D$12="Femenino",R43,U43) -> #REF! | Q43: =+IF($D$13="Activa - 16 a 18 años",Y43,IF($D$13="Activa - 19 a 30 años",AE43,IF($D$13="Activa - 31 a 50 años",AK43,IF($D$13="Activa - Mayor de 50 años",AQ43,IF($D$13="Atletismo de Resistencia",#REF!,IF($D$13="Básquetbol",#REF!,IF($D$13="Fitness Sport",#REF!,IF($D$13="Fútbol",#REF!,IF($D$13="Hockey sobre Césped",#REF!,IF($D$13="Rugby",#REF!,IF($D$13="Tenis",#REF!,#REF!))))))))))) -> #REF! | R43: =+IF($D$13="Activa - 16 a 18 años",Z43,IF($D$13="Activa - 19 a 30 años",AF43,IF($D$13="Activa - 31 a 50 años",AL43,IF($D$13="Activa - Mayor de 50 años",AR43,IF($D$13="Atletismo de Resistencia",#REF!,IF($D$13="Básquetbol",#REF!,IF($D$13="Fitness Sport",#REF!,IF($D$13="Fútbol",#REF!,IF($D$13="Hockey sobre Césped",#REF!,IF($D$13="Rugby",#REF!,IF($D$13="Tenis",#REF!,#REF!))))))))))) -> #REF! | T43: =+IF($D$13="Activa - 16 a 18 años",AB43,IF($D$13="Activa - 19 a 30 años",AH43,IF($D$13="Activa - 31 a 50 años",AN43,IF($D$13="Activa - Mayor de 50 años",AT43,IF($D$13="Atletismo de Resistencia",#REF!,IF($D$13="Básquetbol",#REF!,IF($D$13="Fitness Sport",#REF!,IF($D$13="Fútbol",#REF!,IF($D$13="Hockey sobre Césped",#REF!,IF($D$13="Rugby",#REF!,IF($D$13="Tenis",#REF!,#REF!))))))))))) -> #REF! | U43: =+IF($D$13="Activa - 16 a 18 años",AC43,IF($D$13="Activa - 19 a 30 años",AI43,IF($D$13="Activa - 31 a 50 años",AO43,IF($D$13="Activa - Mayor de 50 años",AU43,IF($D$13="Atletismo de Resistencia",#REF!,IF($D$13="Básquetbol",#REF!,IF($D$13="Fitness Sport",#REF!,IF($D$13="Fútbol",#REF!,IF($D$13="Hockey sobre Césped",#REF!,IF($D$13="Rugby",#REF!,IF($D$13="Tenis",#REF!,#REF!))))))))))) -> #REF! | Y43: 96.832143 | Z43: 5.7972569 | AB43: 93.885577 | AC43: 5.9428086 | AE43: 93.478182 | AF43: 5.6417653 | AH43: 97.256647 | AI43: 8.0043393 | AK43: 96.226087 | AL43: 7.764316 | AN43: 100.3227 | AO43: 7.9683347 | AQ43: 103.93529 | AR43: 8.5697098 | AT43: 101.65854 | AU43: 6.2070515
K44: PERÍMETRO MUSLO MEDIO (cm): | L44: =+IF($D$12="Femenino",Q44,T44) -> #REF! | M44: =+IF($D$12="Femenino",R44,U44) -> #REF! | Q44: =+IF($D$13="Activa - 16 a 18 años",Y44,IF($D$13="Activa - 19 a 30 años",AE44,IF($D$13="Activa - 31 a 50 años",AK44,IF($D$13="Activa - Mayor de 50 años",AQ44,IF($D$13="Atletismo de Resistencia",#REF!,IF($D$13="Básquetbol",#REF!,IF($D$13="Fitness Sport",#REF!,IF($D$13="Fútbol",#REF!,IF($D$13="Hockey sobre Césped",#REF!,IF($D$13="Rugby",#REF!,IF($D$13="Tenis",#REF!,#REF!))))))))))) -> #REF! | R44: =+IF($D$13="Activa - 16 a 18 años",Z44,IF($D$13="Activa - 19 a 30 años",AF44,IF($D$13="Activa - 31 a 50 años",AL44,IF($D$13="Activa - Mayor de 50 años",AR44,IF($D$13="Atletismo de Resistencia",#REF!,IF($D$13="Básquetbol",#REF!,IF($D$13="Fitness Sport",#REF!,IF($D$13="Fútbol",#REF!,IF($D$13="Hockey sobre Césped",#REF!,IF($D$13="Rugby",#REF!,IF($D$13="Tenis",#REF!,#REF!))))))))))) -> #REF! | T44: =+IF($D$13="Activa - 16 a 18 años",AB44,IF($D$13="Activa - 19 a 30 años",AH44,IF($D$13="Activa - 31 a 50 años",AN44,IF($D$13="Activa - Mayor de 50 años",AT44,IF($D$13="Atletismo de Resistencia",#REF!,IF($D$13="Básquetbol",#REF!,IF($D$13="Fitness Sport",#REF!,IF($D$13="Fútbol",#REF!,IF($D$13="Hockey sobre Césped",#REF!,IF($D$13="Rugby",#REF!,IF($D$13="Tenis",#REF!,#REF!))))))))))) -> #REF! | U44: =+IF($D$13="Activa - 16 a 18 años",AC44,IF($D$13="Activa - 19 a 30 años",AI44,IF($D$13="Activa - 31 a 50 años",AO44,IF($D$13="Activa - Mayor de 50 años",AU44,IF($D$13="Atletismo de Resistencia",#REF!,IF($D$13="Básquetbol",#REF!,IF($D$13="Fitness Sport",#REF!,IF($D$13="Fútbol",#REF!,IF($D$13="Hockey sobre Césped",#REF!,IF($D$13="Rugby",#REF!,IF($D$13="Tenis",#REF!,#REF!))))))))))) -> #REF! | Y44: 55.557143 | Z44: 3.8875326 | AB44: 55.2125 | AC44: 4.3947163 | AE44: 52.903636 | AF44: 4.0885098 | AH44: 57.017341 | AI44: 5.0539002 | AK44: 55.269855 | AL44: 5.5253902 | AN44: 57.865031 | AO44: 4.933803 | AQ44: 57.988235 | AR44: 5.0842751 | AT44: 56.868293 | AU44: 3.800292
K45: PERÍMETRO PIERNA (cm): | L45: =+IF($D$12="Femenino",Q45,T45) -> #REF! | M45: =+IF($D$12="Femenino",R45,U45) -> #REF! | Q45: =+IF($D$13="Activa - 16 a 18 años",Y45,IF($D$13="Activa - 19 a 30 años",AE45,IF($D$13="Activa - 31 a 50 años",AK45,IF($D$13="Activa - Mayor de 50 años",AQ45,IF($D$13="Atletismo de Resistencia",#REF!,IF($D$13="Básquetbol",#REF!,IF($D$13="Fitness Sport",#REF!,IF($D$13="Fútbol",#REF!,IF($D$13="Hockey sobre Césped",#REF!,IF($D$13="Rugby",#REF!,IF($D$13="Tenis",#REF!,#REF!))))))))))) -> #REF! | R45: =+IF($D$13="Activa - 16 a 18 años",Z45,IF($D$13="Activa - 19 a 30 años",AF45,IF($D$13="Activa - 31 a 50 años",AL45,IF($D$13="Activa - Mayor de 50 años",AR45,IF($D$13="Atletismo de Resistencia",#REF!,IF($D$13="Básquetbol",#REF!,IF($D$13="Fitness Sport",#REF!,IF($D$13="Fútbol",#REF!,IF($D$13="Hockey sobre Césped",#REF!,IF($D$13="Rugby",#REF!,IF($D$13="Tenis",#REF!,#REF!))))))))))) -> #REF! | T45: =+IF($D$13="Activa - 16 a 18 años",AB45,IF($D$13="Activa - 19 a 30 años",AH45,IF($D$13="Activa - 31 a 50 años",AN45,IF($D$13="Activa - Mayor de 50 años",AT45,IF($D$13="Atletismo de Resistencia",#REF!,IF($D$13="Básquetbol",#REF!,IF($D$13="Fitness Sport",#REF!,IF($D$13="Fútbol",#REF!,IF($D$13="Hockey sobre Césped",#REF!,IF($D$13="Rugby",#REF!,IF($D$13="Tenis",#REF!,#REF!))))))))))) -> #REF! | U45: =+IF($D$13="Activa - 16 a 18 años",AC45,IF($D$13="Activa - 19 a 30 años",AI45,IF($D$13="Activa - 31 a 50 años",AO45,IF($D$13="Activa - Mayor de 50 años",AU45,IF($D$13="Atletismo de Resistencia",#REF!,IF($D$13="Básquetbol",#REF!,IF($D$13="Fitness Sport",#REF!,IF($D$13="Fútbol",#REF!,IF($D$13="Hockey sobre Césped",#REF!,IF($D$13="Rugby",#REF!,IF($D$13="Tenis",#REF!,#REF!))))))))))) -> #REF! | Y45: 34.342857 | Z45: 2.3024027 | AB45: 36.134615 | AC45: 2.7591954 | AE45: 33.816364 | AF45: 2.9803532 | AH45: 36.781503 | AI45: 2.9521187 | AK45: 34.636232 | AL45: 2.6577285 | AN45: 38.060123 | AO45: 3.1918596 | AQ45: 36.058824 | AR45: 2.7796265 | AT45: 37.892683 | AU45: 2.5490577
...

Sheet INF 2º
A2: EVALUACIÓN ANTROPOMÉTRICA
I3: Licenciada Rosana Roldán - www.nuplan.com.ar
J5: 15.75
A6: En DATOS tanto DEMOGRÁFICOS como ANTROPOMÉTRICOS se muestran los valores de la persona medida, y sus resultados en COMPOSICIÓN CORPORAL, en ADIPOSIDAD y en COMPARATIVO DE PERÍMETROS MUSCULARES. | J6: 17.25
J7: 9
A9: DATOS DEMOGRÁFICOS
A11: Nombre y Apellido: | D11: =+'NO TOCAR'!E9 -> 0 | G11: Número de Observación: | I11: =+'NO TOCAR'!E5 -> 2
A12: Sexo: | D12: =+'NO TOCAR'!E10 -> 0 | G12: Fecha de Medición: | I12: =+'NO TOCAR'!E6 -> 0
A13: Actividad Física o Referencia: | D13: =+'NO TOCAR'!E11 -> 0 | G13: Fecha de Nacimiento: | I13: =+'NO TOCAR'!E7 -> 0
A14: Raza, Etnia o Grupo Humano: | D14: =+IF('NO TOCAR'!E12=0,"Blanca o Hispánica",IF('NO TOCAR'!E12=1.1,"Afroamericana","Asiática")) -> Blanca o Hispánica | G14: Edad (años): | I14: =+(I12-I13)/365.25 -> 0
E15: =+'NO TOCAR'!D12 -> 0
A16: DATOS ANTROPOMÉTRICOS
Q17: DATOS REFERENCIALES DE CADA SEXO O GÉNERO
A18: Talla (cm): | E18: =+'NO TOCAR'!E14 -> 0 | F18: Perímetro Torácico (cm): | I18: =+'NO TOCAR'!E22 -> 0
A19: Peso (kg): | E19: =+'NO TOCAR'!E15 -> 0 | F19: Perímetro Cintura (cm): | I19: =+'NO TOCAR'!E23 -> 0
A20: Pliegue Tricipital (mm): | E20: =+'NO TOCAR'!E16 -> 0 | F20: Perímetro Umbilical (cm): | I20: =+'NO TOCAR'!E24 -> 0
A21: Pliegue Subescapular (mm): | E21: =+'NO TOCAR'!E17 -> 0 | F21: Perímetro Cadera (cm): | I21: =+'NO TOCAR'!E25 -> 0
A22: Pliegue Ileocrestal (mm): | E22: =+'NO TOCAR'!E18 -> 0 | F22: Perímetro de Muslo Medio (cm): | I22: =+'NO TOCAR'!E26 -> 0
A23: Pliegue Abdominal (mm): | E23: =+'NO TOCAR'!E19 -> 0 | F23: Perímetro de Pierna (cm): | I23: =+'NO TOCAR'!E27 -> 0 | K23: DATOS REFERENCIALES FINALES | L23: =+Q23 -> #REF! | M23: SEXO | Q23: =+IF($D$13="Activa - 16 a 18 años",Y23,IF($D$13="Activa - 19 a 30 años",AE23,IF($D$13="Activa - 31 a 50 años",AK23,IF($D$13="Activa - Mayor de 50 años",AQ23,IF($D$13="Atletismo de Resistencia",#REF!,IF($D$13="Básquetbol",#REF!,IF($D$13="Fitness Sport",#REF!,IF($D$13="Fútbol",#REF!,IF($D$13="Hockey sobre Césped",#REF!,IF($D$13="Rugby",#REF!,IF($D$13="Tenis",#REF!,#REF!))))))))))) -> #REF! | R23: SEXO | T23: =+IF($D$13="Activa - 16 a 18 años",AB23,IF($D$13="Activa - 19 a 30 años",AH23,IF($D$13="Activa - 31 a 50 años",AN23,IF($D$13="Activa - Mayor de 50 años",AT23,IF($D$13="Atletismo de Resistencia",#REF!,IF($D$13="Básquetbol",#REF!,IF($D$13="Fitness Sport",#REF!,IF($D$13="Fútbol",#REF!,IF($D$13="Hockey sobre Césped",#REF!,IF($D$13="Rugby",#REF!,IF($D$13="Tenis",#REF!,#REF!))))))))))) -> #REF! | U23: SEXO | Y23: Activa - 16 a 18 años | Z23: SEXO | AB23: Activa - 16 a 18 años | AC23: SEXO | AE23: Activa - 19 a 30 años | AF23: SEXO | AH23: Activa - 19 a 30 años | AI23: SEXO | AK23: Activa - 31 a 50 años | AL23: SEXO | AN23: Activa - 31 a 50 años | AO23: SEXO | AQ23: Activa - Mayor de 50 años | AR23: SEXO | AT23: Activa - Mayor de 50 años | AU23: SEXO
A24: Pliegue Muslo Anterior (mm): | E24: =+'NO TOCAR'!E20 -> 0 | F24: Perímetro de Brazo Relajado (cm): | I24: =+'NO TOCAR'!E28 -> 0 | M24: =+IF(D12="Femenino",R24,U24) -> #REF! | R24: =+IF($D$13="Activa - 16 a 18 años",Z24,IF($D$13="Activa - 19 a 30 años",AF24,IF($D$13="Activa - 31 a 50 años",AL24,IF($D$13="Activa - Mayor de 50 años",AR24,IF($D$13="Atletismo de Resistencia",#REF!,IF($D$13="Básquetbol",#REF!,IF($D$13="Fitness Sport",#REF!,IF($D$13="Fútbol",#REF!,IF($D$13="Hockey sobre Césped",#REF!,IF($D$13="Rugby",#REF!,IF($D$13="Tenis",#REF!,#REF!))))))))))) -> #REF! | U24: =+IF($D$13="Activa - 16 a 18 años",AC24,IF($D$13="Activa - 19 a 30 años",AI24,IF($D$13="Activa - 31 a 50 años",AO24,IF($D$13="Activa - Mayor de 50 años",AU24,IF($D$13="Atletismo de Resistencia",#REF!,IF($D$13="Básquetbol",#REF!,IF($D$13="Fitness Sport",#REF!,IF($D$13="Fútbol",#REF!,IF($D$13="Hockey sobre Césped",#REF!,IF($D$13="Rugby",#REF!,IF($D$13="Tenis",#REF!,#REF!))))))))))) -> #REF! | Z24: Femenino | AC24: Masculino | AF24: Femenino | AI24: Masculino | AL24: Femenino | AO24: Masculino | AR24: Femenino | AU24: Masculino
A25: Pliegue Pierna Medial (mm): | E25: =+'NO TOCAR'!E21 -> 0 | F25: Diámetro Bicondíleo de Fémur (cm): | I25: =+'NO TOCAR'!E29 -> 0 | M25: n | R25: n | U25: n | Z25: n | AC25: n | AF25: n | AI25: n | AL25: n | AO25: n | AR25: n | AU25: n
A26: - - - - - - - - - - - - - - - - - - - - - - - - - - - - - - - - - - - - - - - - - - - - - - - - - - - - - - - - | F26: Diámetro Biestiloideo de Muñeca (cm): | I26: =+'NO TOCAR'!E30 -> 0 | M26: =+IF(D12="Femenino",R26,U26) -> #REF! | R26: =+IF($D$13="Activa - 16 a 18 años",Z26,IF($D$13="Activa - 19 a 30 años",AF26,IF($D$13="Activa - 31 a 50 años",AL26,IF($D$13="Activa - Mayor de 50 años",AR26,IF($D$13="Atletismo de Resistencia",#REF!,IF($D$13="Básquetbol",#REF!,IF($D$13="Fitness Sport",#REF!,IF($D$13="Fútbol",#REF!,IF($D$13="Hockey sobre Césped",#REF!,IF($D$13="Rugby",#REF!,IF($D$13="Tenis",#REF!,#REF!))))))))))) -> #REF! | U26: =+IF($D$13="Activa - 16 a 18 años",AC26,IF($D$13="Activa - 19 a 30 años",AI26,IF($D$13="Activa - 31 a 50 años",AO26,IF($D$13="Activa - Mayor de 50 años",AU26,IF($D$13="Atletismo de Resistencia",#REF!,IF($D$13="Básquetbol",#REF!,IF($D$13="Fitness Sport",#REF!,IF($D$13="Fútbol",#REF!,IF($D$13="Hockey sobre Césped",#REF!,IF($D$13="Rugby",#REF!,IF($D$13="Tenis",#REF!,#REF!))))))))))) -> #REF! | Z26: 28 | AC26: 104 | AF26: 55 | AI26: 173 | AL26: 69 | AO26: 163 | AR26: 17 | AU26: 41
A28: VALORES EN COMPOSICIÓN CORPORAL | K28: VARIABLES CORPORALES | L28: MEDIA | M28: D.E. | Q28: MEDIA | R28: D.E. | T28: MEDIA | U28: D.E. | Y28: MEDIA | Z28: D.E. | AB28: MEDIA | AC28: D.E. | AE28: MEDIA | AF28: D.E. | AH28: MEDIA | AI28: D.E. | AK28: MEDIA | AL28: D.E. | AN28: MEDIA | AO28: D.E. | AQ28: MEDIA | AR28: D.E. | AT28: MEDIA | AU28: D.E.
A29: =(0.735*(E20+E25)+1) -> 1 | B29: =(0.61*(E20+E25)+5.1) -> 5.1 | E29: =+(0.29288*(E23+E20+E24+E22)-(0.0005*((E23+E20+E24+E22)^2))+(0.15845*I14)-5.76377) -> -5.76377 | F29: =+(0.29669*(E23+E20+E24+E22)-(0.00043*((E23+E20+E24+E22)^2))+(0.02963*I14)+1.4072) -> 1.4072
A30: Masa Adiposa (%): | E30: =+IF(AND(D12="Femenino",I14<18),B29,IF(AND(D12="Masculino",I14<18),A29,IF(AND(D12="Femenino",I14>=18),F29,E29))) -> -5.76377 | F30: Masa Adiposa (kg): | I30: =+E30*E19/100 -> 0 | K30: PESO (kg): | L30: =+IF($D$12="Femenino",Q30,T30) -> #REF! | M30: =+IF($D$12="Femenino",R30,U30) -> #REF! | Q30: =+IF($D$13="Activa - 16 a 18 años",Y30,IF($D$13="Activa - 19 a 30 años",AE30,IF($D$13="Activa - 31 a 50 años",AK30,IF($D$13="Activa - Mayor de 50 años",AQ30,IF($D$13="Atletismo de Resistencia",#REF!,IF($D$13="Básquetbol",#REF!,IF($D$13="Fitness Sport",#REF!,IF($D$13="Fútbol",#REF!,IF($D$13="Hockey sobre Césped",#REF!,IF($D$13="Rugby",#REF!,IF($D$13="Tenis",#REF!,#REF!))))))))))) -> #REF! | R30: =+IF($D$13="Activa - 16 a 18 años",Z30,IF($D$13="Activa - 19 a 30 años",AF30,IF($D$13="Activa - 31 a 50 años",AL30,IF($D$13="Activa - Mayor de 50 años",AR30,IF($D$13="Atletismo de Resistencia",#REF!,IF($D$13="Básquetbol",#REF!,IF($D$13="Fitness Sport",#REF!,IF($D$13="Fútbol",#REF!,IF($D$13="Hockey sobre Césped",#REF!,IF($D$13="Rugby",#REF!,IF($D$13="Tenis",#REF!,#REF!))))))))))) -> #REF! | T30: =+IF($D$13="Activa - 16 a 18 años",AB30,IF($D$13="Activa - 19 a 30 años",AH30,IF($D$13="Activa - 31 a 50 años",AN30,IF($D$13="Activa - Mayor de 50 años",AT30,IF($D$13="Atletismo de Resistencia",#REF!,IF($D$13="Básquetbol",#REF!,IF($D$13="Fitness Sport",#REF!,IF($D$13="Fútbol",#REF!,IF($D$13="Hockey sobre Césped",#REF!,IF($D$13="Rugby",#REF!,IF($D$13="Tenis",#REF!,#REF!))))))))))) -> #REF! | U30: =+IF($D$13="Activa - 16 a 18 años",AC30,IF($D$13="Activa - 19 a 30 años",AI30,IF($D$13="Activa - 31 a 50 años",AO30,IF($D$13="Activa - Mayor de 50 años",AU30,IF($D$13="Atletismo de Resistencia",#REF!,IF($D$13="Básquetbol",#REF!,IF($D$13="Fitness Sport",#REF!,IF($D$13="Fútbol",#REF!,IF($D$13="Hockey sobre Césped",#REF!,IF($D$13="Rugby",#REF!,IF($D$13="Tenis",#REF!,#REF!))))))))))) -> #REF! | Y30: 59.889286 | Z30: 8.2800223 | AB30: 69.255769 | AC30: 9.6711846 | AE30: 55.922727 | AF30: 7.2048133 | AH30: 75.459249 | AI30: 12.753859 | AK30: 59.762319 | AL30: 9.4506046 | AN30: 80.483129 | AO30: 14.090058 | AQ30: 68.370588 | AR30: 9.7891371 | AT30: 84.168293 | AU30: 14.005672
A31: Referencia (Media ± ½ Desvío): | D31: VA /2 | E31: =+CONCATENATE(FIXED(L33,1)," ± ",FIXED(M33/2,1)) -> #REF! | F31: Referencia (Media ± ½ Desvío): | I31: =+CONCATENATE(FIXED(L32,1)," ± ",FIXED(M32/2,1)) -> #REF! | J31: =+IF(I30<L32-M32*1.5,"Excelente",IF(I30<L32-M32/2,"Muy Buena",IF(I30<=L32+M32/2,"Buena",IF(I30<=L32+M32*1.5,"Regular","No Satisfactoria")))) -> #REF! | K31: TALLA (kg): | L31: =+IF($D$12="Femenino",Q31,T31) -> #REF! | M31: =+IF($D$12="Femenino",R31,U31) -> #REF! | Q31: =+IF($D$13="Activa - 16 a 18 años",Y31,IF($D$13="Activa - 19 a 30 años",AE31,IF($D$13="Activa - 31 a 50 años",AK31,IF($D$13="Activa - Mayor de 50 años",AQ31,IF($D$13="Atletismo de Resistencia",#REF!,IF($D$13="Básquetbol",#REF!,IF($D$13="Fitness Sport",#REF!,IF($D$13="Fútbol",#REF!,IF($D$13="Hockey sobre Césped",#REF!,IF($D$13="Rugby",#REF!,IF($D$13="Tenis",#REF!,#REF!))))))))))) -> #REF! | R31: =+IF($D$13="Activa - 16 a 18 años",Z31,IF($D$13="Activa - 19 a 30 años",AF31,IF($D$13="Activa - 31 a 50 años",AL31,IF($D$13="Activa - Mayor de 50 años",AR31,IF($D$13="Atletismo de Resistencia",#REF!,IF($D$13="Básquetbol",#REF!,IF($D$13="Fitness Sport",#REF!,IF($D$13="Fútbol",#REF!,IF($D$13="Hockey sobre Césped",#REF!,IF($D$13="Rugby",#REF!,IF($D$13="Tenis",#REF!,#REF!))))))))))) -> #REF! | T31: =+IF($D$13="Activa - 16 a 18 años",AB31,IF($D$13="Activa - 19 a 30 años",AH31,IF($D$13="Activa - 31 a 50 años",AN31,IF($D$13="Activa - Mayor de 50 años",AT31,IF($D$13="Atletismo de Resistencia",#REF!,IF($D$13="Básquetbol",#REF!,IF($D$13="Fitness Sport",#REF!,IF($D$13="Fútbol",#REF!,IF($D$13="Hockey sobre Césped",#REF!,IF($D$13="Rugby",#REF!,IF($D$13="Tenis",#REF!,#REF!))))))))))) -> #REF! | U31: =+IF($D$13="Activa - 16 a 18 años",AC31,IF($D$13="Activa - 19 a 30 años",AI31,IF($D$13="Activa - 31 a 50 años",AO31,IF($D$13="Activa - Mayor de 50 años",AU31,IF($D$13="Atletismo de Resistencia",#REF!,IF($D$13="Básquetbol",#REF!,IF($D$13="Fitness Sport",#REF!,IF($D$13="Fútbol",#REF!,IF($D$13="Hockey sobre Césped",#REF!,IF($D$13="Rugby",#REF!,IF($D$13="Tenis",#REF!,#REF!))))))))))) -> #REF! | Y31: 163.49643 | Z31: 6.6638039 | AB31: 174.32115 | AC31: 7.3435749 | AE31: 161.47873 | AF31: 6.133285 | AH31: 175.45665 | AI31: 6.4624609 | AK31: 161.22029 | AL31: 6.0620221 | AN31: 174.20675 | AO31: 7.1526834 | AQ31: 157.42941 | AR31: 4.2245954 | AT31: 174.30732 | AU31: 5.9086119
K32: MASA ADIPOSA (kg): | L32: =+IF($D$12="Femenino",Q32,T32) -> #REF! | M32: =+IF($D$12="Femenino",R32,U32) -> #REF! | Q32: =+IF($D$13="Activa - 16 a 18 años",Y32,IF($D$13="Activa - 19 a 30 años",AE32,IF($D$13="Activa - 31 a 50 años",AK32,IF($D$13="Activa - Mayor de 50 años",AQ32,IF($D$13="Atletismo de Resistencia",#REF!,IF($D$13="Básquetbol",#REF!,IF($D$13="Fitness Sport",#REF!,IF($D$13="Fútbol",#REF!,IF($D$13="Hockey sobre Césped",#REF!,IF($D$13="Rugby",#REF!,IF($D$13="Tenis",#REF!,#REF!))))))))))) -> #REF! | R32: =+IF($D$13="Activa - 16 a 18 años",Z32,IF($D$13="Activa - 19 a 30 años",AF32,IF($D$13="Activa - 31 a 50 años",AL32,IF($D$13="Activa - Mayor de 50 años",AR32,IF($D$13="Atletismo de Resistencia",#REF!,IF($D$13="Básquetbol",#REF!,IF($D$13="Fitness Sport",#REF!,IF($D$13="Fútbol",#REF!,IF($D$13="Hockey sobre Césped",#REF!,IF($D$13="Rugby",#REF!,IF($D$13="Tenis",#REF!,#REF!))))))))))) -> #REF! | T32: =+IF($D$13="Activa - 16 a 18 años",AB32,IF($D$13="Activa - 19 a 30 años",AH32,IF($D$13="Activa - 31 a 50 años",AN32,IF($D$13="Activa - Mayor de 50 años",AT32,IF($D$13="Atletismo de Resistencia",#REF!,IF($D$13="Básquetbol",#REF!,IF($D$13="Fitness Sport",#REF!,IF($D$13="Fútbol",#REF!,IF($D$13="Hockey sobre Césped",#REF!,IF($D$13="Rugby",#REF!,IF($D$13="Tenis",#REF!,#REF!))))))))))) -> #REF! | U32: =+IF($D$13="Activa - 16 a 18 años",AC32,IF($D$13="Activa - 19 a 30 años",AI32,IF($D$13="Activa - 31 a 50 años",AO32,IF($D$13="Activa - Mayor de 50 años",AU32,IF($D$13="Atletismo de Resistencia",#REF!,IF($D$13="Básquetbol",#REF!,IF($D$13="Fitness Sport",#REF!,IF($D$13="Fútbol",#REF!,IF($D$13="Hockey sobre Césped",#REF!,IF($D$13="Rugby",#REF!,IF($D$13="Tenis",#REF!,#REF!))))))))))) -> #REF! | Y32: 15.12565 | Z32: 4.7014942 | AB32: 10.696169 | AC32: 5.1149452 | AE32: 12.381169 | AF32: 4.3077838 | AH32: 10.920301 | AI32: 7.1803911 | AK32: 14.242999 | AL32: 5.8936537 | AN32: 16.693186 | AO32: 8.1510109 | AQ32: 21.006161 | AR32: 6.2233103 | AT32: 21.534002 | AU32: 8.7308852
A33: Masa Muscular (%): | E33: =+I33*100/E19 -> #DIV/0! | F33: Masa Muscular (kg): | I33: =+(E18/100)*(0.00744*(I24-3.1416*(E20/10))^2+0.00088*(I22-3.1416*(E24/10))^2+0.00441*(I23-3.1416*(E25/10))^2)+(2.4*(IF(D12="Masculino",1,0)))-(0.048*I14)+E15+7.8 -> 7.8 | K33: MASA ADIPOSA (%): | L33: =+IF($D$12="Femenino",Q33,T33) -> #REF! | M33: =+IF($D$12="Femenino",R33,U33) -> #REF! | Q33: =+IF($D$13="Activa - 16 a 18 años",Y33,IF($D$13="Activa - 19 a 30 años",AE33,IF($D$13="Activa - 31 a 50 años",AK33,IF($D$13="Activa - Mayor de 50 años",AQ33,IF($D$13="Atletismo de Resistencia",#REF!,IF($D$13="Básquetbol",#REF!,IF($D$13="Fitness Sport",#REF!,IF($D$13="Fútbol",#REF!,IF($D$13="Hockey sobre Césped",#REF!,IF($D$13="Rugby",#REF!,IF($D$13="Tenis",#REF!,#REF!))))))))))) -> #REF! | R33: =+IF($D$13="Activa - 16 a 18 años",Z33,IF($D$13="Activa - 19 a 30 años",AF33,IF($D$13="Activa - 31 a 50 años",AL33,IF($D$13="Activa - Mayor de 50 años",AR33,IF($D$13="Atletismo de Resistencia",#REF!,IF($D$13="Básquetbol",#REF!,IF($D$13="Fitness Sport",#REF!,IF($D$13="Fútbol",#REF!,IF($D$13="Hockey sobre Césped",#REF!,IF($D$13="Rugby",#REF!,IF($D$13="Tenis",#REF!,#REF!))))))))))) -> #REF! | T33: =+IF($D$13="Activa - 16 a 18 años",AB33,IF($D$13="Activa - 19 a 30 años",AH33,IF($D$13="Activa - 31 a 50 años",AN33,IF($D$13="Activa - Mayor de 50 años",AT33,IF($D$13="Atletismo de Resistencia",#REF!,IF($D$13="Básquetbol",#REF!,IF($D$13="Fitness Sport",#REF!,IF($D$13="Fútbol",#REF!,IF($D$13="Hockey sobre Césped",#REF!,IF($D$13="Rugby",#REF!,IF($D$13="Tenis",#REF!,#REF!))))))))))) -> #REF! | U33: =+IF($D$13="Activa - 16 a 18 años",AC33,IF($D$13="Activa - 19 a 30 años",AI33,IF($D$13="Activa - 31 a 50 años",AO33,IF($D$13="Activa - Mayor de 50 años",AU33,IF($D$13="Atletismo de Resistencia",#REF!,IF($D$13="Básquetbol",#REF!,IF($D$13="Fitness Sport",#REF!,IF($D$13="Fútbol",#REF!,IF($D$13="Hockey sobre Césped",#REF!,IF($D$13="Rugby",#REF!,IF($D$13="Tenis",#REF!,#REF!))))))))))) -> #REF! | Y33: 25.066607 | Z33: 5.8554364 | AB33: 15.201755 | AC33: 5.9492562 | AE33: 21.770553 | AF33: 5.1861666 | AH33: 13.689817 | AI33: 6.8496419 | AK33: 23.084948 | AL33: 6.4873064 | AN33: 19.987753 | AO33: 6.516567 | AQ33: 30.137324 | AR33: 5.5134903 | AT33: 24.855993 | AU33: 6.1267433
A34: Referencia (Media ± ½ Desvío): | E34: =+CONCATENATE(FIXED(L35,1)," ± ",FIXED(M35/2,1)) -> #REF! | F34: Referencia (Media ± ½ Desvío): | I34: =+CONCATENATE(FIXED(L34,1)," ± ",FIXED(M34/2,1)) -> #REF! | J34: =+IF(I33>L34+M34*1.5,"Excelente",IF(I33>L34+M34/2,"Muy Bueno",IF(I33>=L34-M34/2,"Bueno",IF(I33>=L34-M34*1.5,"Regular","No Satisfactorio")))) -> #REF! | K34: MASA MUSCULAR (kg): | L34: =+IF($D$12="Femenino",Q34,T34) -> #REF! | M34: =+IF($D$12="Femenino",R34,U34) -> #REF! | Q34: =+IF($D$13="Activa - 16 a 18 años",Y34,IF($D$13="Activa - 19 a 30 años",AE34,IF($D$13="Activa - 31 a 50 años",AK34,IF($D$13="Activa - Mayor de 50 años",AQ34,IF($D$13="Atletismo de Resistencia",#REF!,IF($D$13="Básquetbol",#REF!,IF($D$13="Fitness Sport",#REF!,IF($D$13="Fútbol",#REF!,IF($D$13="Hockey sobre Césped",#REF!,IF($D$13="Rugby",#REF!,IF($D$13="Tenis",#REF!,#REF!))))))))))) -> #REF! | R34: =+IF($D$13="Activa - 16 a 18 años",Z34,IF($D$13="Activa - 19 a 30 años",AF34,IF($D$13="Activa - 31 a 50 años",AL34,IF($D$13="Activa - Mayor de 50 años",AR34,IF($D$13="Atletismo de Resistencia",#REF!,IF($D$13="Básquetbol",#REF!,IF($D$13="Fitness Sport",#REF!,IF($D$13="Fútbol",#REF!,IF($D$13="Hockey sobre Césped",#REF!,IF($D$13="Rugby",#REF!,IF($D$13="Tenis",#REF!,#REF!))))))))))) -> #REF! | T34: =+IF($D$13="Activa - 16 a 18 años",AB34,IF($D$13="Activa - 19 a 30 años",AH34,IF($D$13="Activa - 31 a 50 años",AN34,IF($D$13="Activa - Mayor de 50 años",AT34,IF($D$13="Atletismo de Resistencia",#REF!,IF($D$13="Básquetbol",#REF!,IF($D$13="Fitness Sport",#REF!,IF($D$13="Fútbol",#REF!,IF($D$13="Hockey sobre Césped",#REF!,IF($D$13="Rugby",#REF!,IF($D$13="Tenis",#REF!,#REF!))))))))))) -> #REF! | U34: =+IF($D$13="Activa - 16 a 18 años",AC34,IF($D$13="Activa - 19 a 30 años",AI34,IF($D$13="Activa - 31 a 50 años",AO34,IF($D$13="Activa - Mayor de 50 años",AU34,IF($D$13="Atletismo de Resistencia",#REF!,IF($D$13="Básquetbol",#REF!,IF($D$13="Fitness Sport",#REF!,IF($D$13="Fútbol",#REF!,IF($D$13="Hockey sobre Césped",#REF!,IF($D$13="Rugby",#REF!,IF($D$13="Tenis",#REF!,#REF!))))))))))) -> #REF! | Y34: 21.39283 | Z34: 2.4830093 | AB34: 29.863816 | AC34: 3.3831829 | AE34: 20.28566 | AF34: 1.8217342 | AH34: 31.444974 | AI34: 3.8720819 | AK34: 20.768183 | AL34: 2.0123254 | AN34: 31.543881 | AO34: 4.1832887 | AQ34: 20.253511 | AR34: 2.2490133 | AT34: 29.754901 | AU34: 3.2538854
